<?xml version="1.0" ?>
<!-- =================================================================================== -->
<!-- |    This document was autogenerated by xacro from jupiterobot2_arm.urdf.xacro    | -->
<!-- |    EDITING THIS FILE BY HAND IS NOT RECOMMENDED                                 | -->
<!-- =================================================================================== -->
<!-- Describe URDF for Jupiter2 Arm -->
<robot name="jupiterobot2_arm">
  <!-- As we don't have here a robot base, add a base_link link as its location reference -->
  <link name="arm_mount_link"/>
  <link name="arm_base_link"/>
  <joint name="arm_base_joint" type="fixed">
    <origin xyz="0.0 0.0 -0.015"/>
    <parent link="arm_mount_link"/>
    <child link="arm_base_link"/>
  </joint>
  <joint name="arm1_servo_joint" type="fixed">
    <origin rpy="1.570796326795 0 1.570796326795" xyz="0 0 0"/>
    <parent link="arm_base_link"/>
    <child link="arm1_servo_link"/>
  </joint>
  <link name="arm1_servo_link">
    <visual>
      <origin rpy="0 0 0" xyz="0 0 0"/>
      <geometry>
        <mesh filename="package://jupiterobot2_arm_description/meshes/ax12_box.stl" scale="0.001 0.001 0.001"/>
      </geometry>
      <material name="Black"/>
    </visual>
    <collision>
      <origin rpy="0 0 0" xyz="0.0 0.0 -0.01241"/>
      <geometry>
        <box size="0.025 0.038 0.04762"/>
      </geometry>
    </collision>
    <inertial>
      <origin xyz="0 0 0"/>
      <mass value="0.055"/>
      <inertia ixx="0.000017012" ixy="0.0" ixz="0.0" iyy="0.000013258" iyz="0.0" izz="0.000009483"/>
    </inertial>
  </link>
  <gazebo reference="arm1_servo_link">
    <material>Gazebo/Black</material>
    <selfCollide>true</selfCollide>
    <gravity>true</gravity>
  </gazebo>
  <joint name="arm1_joint" type="revolute">
    <origin rpy="-1.570796326795 1.570796326795 3.14159265359" xyz="0 0.019 0"/>
    <axis xyz="0 0 -1"/>
    <limit effort="30" lower="-2.617" upper="2.617" velocity="1.571"/>
    <dynamics friction="0.13"/>
    <parent link="arm1_servo_link"/>
    <child link="arm1_link"/>
  </joint>
  <link name="arm1_link">
    <visual>
      <origin rpy="0 0 0" xyz="0 0 0"/>
      <geometry>
        <mesh filename="package://jupiterobot2_arm_description/meshes/F3.stl" scale="0.001 0.001 0.001"/>
      </geometry>
      <material name="White"/>
    </visual>
    <collision>
      <origin rpy="0 0 0" xyz="0.0 0.0 -0.0045"/>
      <geometry>
        <box size="0.025 0.038 0.009"/>
      </geometry>
    </collision>
    <inertial>
      <origin xyz="0 0 -0.004"/>
      <!--0.025*0.038*0.008-->
      <mass value="0.005"/>
      <inertia ixx="6.2833e-07" ixy="0.0" ixz="0.0" iyy="2.870833e-07" iyz="0.0" izz="8.620833e-07"/>
    </inertial>
  </link>
  <gazebo reference="arm1_link">
    <material>Gazebo/White</material>
    <selfCollide>true</selfCollide>
    <gravity>true</gravity>
  </gazebo>
  <joint name="arm2_servo_joint" type="fixed">
    <origin rpy="0 3.14159265359 0" xyz="0 0 -0.041499999999999995"/>
    <parent link="arm1_link"/>
    <child link="arm2_servo_link"/>
  </joint>
  <link name="arm2_servo_link">
    <visual>
      <origin rpy="0 0 0" xyz="0 0 0"/>
      <geometry>
        <mesh filename="package://jupiterobot2_arm_description/meshes/ax12_box.stl" scale="0.001 0.001 0.001"/>
      </geometry>
      <material name="Black"/>
    </visual>
    <collision>
      <origin rpy="0 0 0" xyz="0.0 0.0 -0.01241"/>
      <geometry>
        <box size="0.025 0.038 0.04762"/>
      </geometry>
    </collision>
    <inertial>
      <origin xyz="0 0 0"/>
      <mass value="0.055"/>
      <inertia ixx="0.000017012" ixy="0.0" ixz="0.0" iyy="0.000013258" iyz="0.0" izz="0.000009483"/>
    </inertial>
  </link>
  <gazebo reference="arm2_servo_link">
    <material>Gazebo/Black</material>
    <selfCollide>true</selfCollide>
    <gravity>true</gravity>
  </gazebo>
  <joint name="arm2_joint" type="revolute">
    <origin rpy="0 0 0" xyz="0 0 0"/>
    <axis xyz="0 1 0"/>
    <limit effort="30" lower="-2.617" upper="2.617" velocity="1.571"/>
    <dynamics friction="0.13"/>
    <parent link="arm2_servo_link"/>
    <child link="arm2_link"/>
  </joint>
  <link name="arm2_link">
    <visual>
      <origin rpy="0 0 0" xyz="0 0 0"/>
      <geometry>
        <mesh filename="package://jupiterobot2_arm_description/meshes/F4.stl" scale="0.001 0.001 0.001"/>
      </geometry>
      <material name="White"/>
    </visual>
    <collision>
      <origin rpy="0 0 0" xyz="0.0 0.0 0.0215"/>
      <geometry>
        <box size="0.028 0.0485 0.065"/>
      </geometry>
    </collision>
    <inertial>
      <origin xyz="0 0 0.03"/>
      <!--0.028*0.048*0.0635-->
      <mass value="0.019"/>
      <inertia ixx="1.003239583e-05" ixy="0.0" ixz="0.0" iyy="7.625729167e-06" iyz="0.0" izz="4.88933e-06"/>
    </inertial>
  </link>
  <gazebo reference="arm2_link">
    <material>Gazebo/White</material>
    <selfCollide>true</selfCollide>
    <gravity>true</gravity>
  </gazebo>
  <joint name="arm2_F10_1_joint" type="fixed">
    <origin rpy="0 0 0" xyz="0 0 0.0545"/>
    <parent link="arm2_link"/>
    <child link="arm2_F10_1_link"/>
  </joint>
  <link name="arm2_F10_1_link">
    <visual>
      <origin rpy="0 0 0" xyz="0 0 0"/>
      <geometry>
        <mesh filename="package://jupiterobot2_arm_description/meshes/F10.stl" scale="0.001 0.001 0.001"/>
      </geometry>
      <material name="White"/>
    </visual>
    <collision>
      <origin rpy="0 0 0" xyz="0.0 0.0 0.0"/>
      <geometry>
        <box size="0.025 0.038 0.004"/>
      </geometry>
    </collision>
    <inertial>
      <origin xyz="0 0 0"/>
      <!--0.025*0.038*0.004-->
      <mass value="0.0033"/>
      <inertia ixx="4.015e-07" ixy="0.0" ixz="0.0" iyy="1.76275e-07" iyz="0.0" izz="5.68975e-07"/>
    </inertial>
  </link>
  <gazebo reference="arm2_F10_1_link">
    <material>Gazebo/White</material>
    <selfCollide>true</selfCollide>
    <gravity>true</gravity>
  </gazebo>
  <joint name="arm2_F10_2_joint" type="fixed">
    <origin rpy="0 0 0" xyz="0 0 0.004"/>
    <parent link="arm2_F10_1_link"/>
    <child link="arm2_F10_2_link"/>
  </joint>
  <link name="arm2_F10_2_link">
    <visual>
      <origin rpy="0 0 0" xyz="0 0 0"/>
      <geometry>
        <mesh filename="package://jupiterobot2_arm_description/meshes/F10.stl" scale="0.001 0.001 0.001"/>
      </geometry>
      <material name="White"/>
    </visual>
    <collision>
      <origin rpy="0 0 0" xyz="0.0 0.0 0.0"/>
      <geometry>
        <box size="0.025 0.038 0.004"/>
      </geometry>
    </collision>
    <inertial>
      <origin xyz="0 0 0"/>
      <!--0.025*0.038*0.004-->
      <mass value="0.0033"/>
      <inertia ixx="4.015e-07" ixy="0.0" ixz="0.0" iyy="1.76275e-07" iyz="0.0" izz="5.68975e-07"/>
    </inertial>
  </link>
  <gazebo reference="arm2_F10_2_link">
    <material>Gazebo/White</material>
    <selfCollide>true</selfCollide>
    <gravity>true</gravity>
  </gazebo>
  <joint name="arm2_F10_3_joint" type="fixed">
    <origin rpy="0 0 0" xyz="0 0 0.004"/>
    <parent link="arm2_F10_2_link"/>
    <child link="arm2_F10_3_link"/>
  </joint>
  <link name="arm2_F10_3_link">
    <visual>
      <origin rpy="0 0 0" xyz="0 0 0"/>
      <geometry>
        <mesh filename="package://jupiterobot2_arm_description/meshes/F10.stl" scale="0.001 0.001 0.001"/>
      </geometry>
      <material name="White"/>
    </visual>
    <collision>
      <origin rpy="0 0 0" xyz="0.0 0.0 0.0"/>
      <geometry>
        <box size="0.025 0.038 0.004"/>
      </geometry>
    </collision>
    <inertial>
      <origin xyz="0 0 0"/>
      <!--0.025*0.038*0.004-->
      <mass value="0.0033"/>
      <inertia ixx="4.015e-07" ixy="0.0" ixz="0.0" iyy="1.76275e-07" iyz="0.0" izz="5.68975e-07"/>
    </inertial>
  </link>
  <gazebo reference="arm2_F10_3_link">
    <material>Gazebo/White</material>
    <selfCollide>true</selfCollide>
    <gravity>true</gravity>
  </gazebo>
  <joint name="arm2_F3_joint" type="fixed">
    <origin rpy="0 3.14159265359 0" xyz="0 0 0.002"/>
    <parent link="arm2_F10_3_link"/>
    <child link="arm2_F3_link"/>
  </joint>
  <link name="arm2_F3_link">
    <visual>
      <origin rpy="0 0 0" xyz="0 0 0"/>
      <geometry>
        <mesh filename="package://jupiterobot2_arm_description/meshes/F3.stl" scale="0.001 0.001 0.001"/>
      </geometry>
      <material name="White"/>
    </visual>
    <collision>
      <origin rpy="0 0 0" xyz="0.0 0.0 -0.0045"/>
      <geometry>
        <box size="0.025 0.038 0.009"/>
      </geometry>
    </collision>
    <inertial>
      <origin xyz="0 0 -0.004"/>
      <!--0.025*0.038*0.008-->
      <mass value="0.005"/>
      <inertia ixx="6.2833e-07" ixy="0.0" ixz="0.0" iyy="2.870833e-07" iyz="0.0" izz="8.620833e-07"/>
    </inertial>
  </link>
  <gazebo reference="arm2_F3_link">
    <material>Gazebo/White</material>
    <selfCollide>true</selfCollide>
    <gravity>true</gravity>
  </gazebo>
  <joint name="arm3_servo_joint" type="fixed">
    <origin rpy="0 3.14159265359 0" xyz="0 0 -0.041499999999999995"/>
    <parent link="arm2_F3_link"/>
    <child link="arm3_servo_link"/>
  </joint>
  <link name="arm3_servo_link">
    <visual>
      <origin rpy="0 0 0" xyz="0 0 0"/>
      <geometry>
        <mesh filename="package://jupiterobot2_arm_description/meshes/ax12_box.stl" scale="0.001 0.001 0.001"/>
      </geometry>
      <material name="Black"/>
    </visual>
    <collision>
      <origin rpy="0 0 0" xyz="0.0 0.0 -0.01241"/>
      <geometry>
        <box size="0.025 0.038 0.04762"/>
      </geometry>
    </collision>
    <inertial>
      <origin xyz="0 0 0"/>
      <mass value="0.055"/>
      <inertia ixx="0.000017012" ixy="0.0" ixz="0.0" iyy="0.000013258" iyz="0.0" izz="0.000009483"/>
    </inertial>
  </link>
  <gazebo reference="arm3_servo_link">
    <material>Gazebo/Black</material>
    <selfCollide>true</selfCollide>
    <gravity>true</gravity>
  </gazebo>
  <joint name="arm3_joint" type="revolute">
    <origin rpy="0 0 0" xyz="0 0 0"/>
    <axis xyz="0 1 0"/>
    <limit effort="30" lower="-2.617" upper="2.617" velocity="1.571"/>
    <dynamics friction="0.13"/>
    <parent link="arm3_servo_link"/>
    <child link="arm3_link"/>
  </joint>
  <link name="arm3_link">
    <visual>
      <origin rpy="0 0 0" xyz="0 0 0"/>
      <geometry>
        <mesh filename="package://jupiterobot2_arm_description/meshes/F4.stl" scale="0.001 0.001 0.001"/>
      </geometry>
      <material name="White"/>
    </visual>
    <collision>
      <origin rpy="0 0 0" xyz="0.0 0.0 0.0215"/>
      <geometry>
        <box size="0.028 0.0485 0.065"/>
      </geometry>
    </collision>
    <inertial>
      <origin xyz="0 0 0.03"/>
      <!--0.028*0.048*0.0635-->
      <mass value="0.019"/>
      <inertia ixx="1.003239583e-05" ixy="0.0" ixz="0.0" iyy="7.625729167e-06" iyz="0.0" izz="4.88933e-06"/>
    </inertial>
  </link>
  <gazebo reference="arm3_link">
    <material>Gazebo/White</material>
    <selfCollide>true</selfCollide>
    <gravity>true</gravity>
  </gazebo>
  <joint name="arm3_F10_1_joint" type="fixed">
    <origin rpy="0 0 0" xyz="0 0 0.0545"/>
    <parent link="arm3_link"/>
    <child link="arm3_F10_1_link"/>
  </joint>
  <link name="arm3_F10_1_link">
    <visual>
      <origin rpy="0 0 0" xyz="0 0 0"/>
      <geometry>
        <mesh filename="package://jupiterobot2_arm_description/meshes/F10.stl" scale="0.001 0.001 0.001"/>
      </geometry>
      <material name="White"/>
    </visual>
    <collision>
      <origin rpy="0 0 0" xyz="0.0 0.0 0.0"/>
      <geometry>
        <box size="0.025 0.038 0.004"/>
      </geometry>
    </collision>
    <inertial>
      <origin xyz="0 0 0"/>
      <!--0.025*0.038*0.004-->
      <mass value="0.0033"/>
      <inertia ixx="4.015e-07" ixy="0.0" ixz="0.0" iyy="1.76275e-07" iyz="0.0" izz="5.68975e-07"/>
    </inertial>
  </link>
  <gazebo reference="arm3_F10_1_link">
    <material>Gazebo/White</material>
    <selfCollide>true</selfCollide>
    <gravity>true</gravity>
  </gazebo>
  <joint name="arm3_F10_2_joint" type="fixed">
    <origin rpy="0 0 0" xyz="0 0 0.004"/>
    <parent link="arm3_F10_1_link"/>
    <child link="arm3_F10_2_link"/>
  </joint>
  <link name="arm3_F10_2_link">
    <visual>
      <origin rpy="0 0 0" xyz="0 0 0"/>
      <geometry>
        <mesh filename="package://jupiterobot2_arm_description/meshes/F10.stl" scale="0.001 0.001 0.001"/>
      </geometry>
      <material name="White"/>
    </visual>
    <collision>
      <origin rpy="0 0 0" xyz="0.0 0.0 0.0"/>
      <geometry>
        <box size="0.025 0.038 0.004"/>
      </geometry>
    </collision>
    <inertial>
      <origin xyz="0 0 0"/>
      <!--0.025*0.038*0.004-->
      <mass value="0.0033"/>
      <inertia ixx="4.015e-07" ixy="0.0" ixz="0.0" iyy="1.76275e-07" iyz="0.0" izz="5.68975e-07"/>
    </inertial>
  </link>
  <gazebo reference="arm3_F10_2_link">
    <material>Gazebo/White</material>
    <selfCollide>true</selfCollide>
    <gravity>true</gravity>
  </gazebo>
  <joint name="arm3_F10_3_joint" type="fixed">
    <origin rpy="0 0 0" xyz="0 0 0.004"/>
    <parent link="arm3_F10_2_link"/>
    <child link="arm3_F10_3_link"/>
  </joint>
  <link name="arm3_F10_3_link">
    <visual>
      <origin rpy="0 0 0" xyz="0 0 0"/>
      <geometry>
        <mesh filename="package://jupiterobot2_arm_description/meshes/F10.stl" scale="0.001 0.001 0.001"/>
      </geometry>
      <material name="White"/>
    </visual>
    <collision>
      <origin rpy="0 0 0" xyz="0.0 0.0 0.0"/>
      <geometry>
        <box size="0.025 0.038 0.004"/>
      </geometry>
    </collision>
    <inertial>
      <origin xyz="0 0 0"/>
      <!--0.025*0.038*0.004-->
      <mass value="0.0033"/>
      <inertia ixx="4.015e-07" ixy="0.0" ixz="0.0" iyy="1.76275e-07" iyz="0.0" izz="5.68975e-07"/>
    </inertial>
  </link>
  <gazebo reference="arm3_F10_3_link">
    <material>Gazebo/White</material>
    <selfCollide>true</selfCollide>
    <gravity>true</gravity>
  </gazebo>
  <joint name="arm3_F3_joint" type="fixed">
    <origin rpy="0 3.14159265359 0" xyz="0 0 0.002"/>
    <parent link="arm3_F10_3_link"/>
    <child link="arm3_F3_link"/>
  </joint>
  <link name="arm3_F3_link">
    <visual>
      <origin rpy="0 0 0" xyz="0 0 0"/>
      <geometry>
        <mesh filename="package://jupiterobot2_arm_description/meshes/F3.stl" scale="0.001 0.001 0.001"/>
      </geometry>
      <material name="White"/>
    </visual>
    <collision>
      <origin rpy="0 0 0" xyz="0.0 0.0 -0.0045"/>
      <geometry>
        <box size="0.025 0.038 0.009"/>
      </geometry>
    </collision>
    <inertial>
      <origin xyz="0 0 -0.004"/>
      <!--0.025*0.038*0.008-->
      <mass value="0.005"/>
      <inertia ixx="6.2833e-07" ixy="0.0" ixz="0.0" iyy="2.870833e-07" iyz="0.0" izz="8.620833e-07"/>
    </inertial>
  </link>
  <gazebo reference="arm3_F3_link">
    <material>Gazebo/White</material>
    <selfCollide>true</selfCollide>
    <gravity>true</gravity>
  </gazebo>
  <joint name="arm4_servo_joint" type="fixed">
    <origin rpy="0 3.14159265359 0" xyz="0 0 -0.041499999999999995"/>
    <parent link="arm3_F3_link"/>
    <child link="arm4_servo_link"/>
  </joint>
  <link name="arm4_servo_link">
    <visual>
      <origin rpy="0 0 0" xyz="0 0 0"/>
      <geometry>
        <mesh filename="package://jupiterobot2_arm_description/meshes/ax12_box.stl" scale="0.001 0.001 0.001"/>
      </geometry>
      <material name="Black"/>
    </visual>
    <collision>
      <origin rpy="0 0 0" xyz="0.0 0.0 -0.01241"/>
      <geometry>
        <box size="0.025 0.038 0.04762"/>
      </geometry>
    </collision>
    <inertial>
      <origin xyz="0 0 0"/>
      <mass value="0.055"/>
      <inertia ixx="0.000017012" ixy="0.0" ixz="0.0" iyy="0.000013258" iyz="0.0" izz="0.000009483"/>
    </inertial>
  </link>
  <gazebo reference="arm4_servo_link">
    <material>Gazebo/Black</material>
    <selfCollide>true</selfCollide>
    <gravity>true</gravity>
  </gazebo>
  <joint name="arm4_joint" type="revolute">
    <origin rpy="0 0 0" xyz="0 0 0"/>
    <axis xyz="0 1 0"/>
    <limit effort="30" lower="-1.745" upper="1.745" velocity="1.571"/>
    <dynamics friction="0.13"/>
    <parent link="arm4_servo_link"/>
    <child link="arm4_link"/>
  </joint>
  <link name="arm4_link">
    <visual>
      <origin rpy="0 0 0" xyz="0 0 0"/>
      <geometry>
        <mesh filename="package://jupiterobot2_arm_description/meshes/F2.stl" scale="0.001 0.001 0.001"/>
      </geometry>
      <material name="White"/>
    </visual>
    <collision>
      <origin rpy="0 0 0" xyz="0.0 0.0 0.00775"/>
      <geometry>
        <box size="0.025 0.0485 0.0375"/>
      </geometry>
    </collision>
    <inertial>
      <origin xyz="0 0 0.015"/>
      <!--0.025*0.048*0.0375-->
      <mass value="0.0115"/>
      <inertia ixx="3.55565625e-06" ixy="0.0" ixz="0.0" iyy="1.946614583e-06" iyz="0.0" izz="2.80695833e-06"/>
    </inertial>
  </link>
  <gazebo reference="arm4_link">
    <material>Gazebo/White</material>
    <selfCollide>true</selfCollide>
    <gravity>true</gravity>
  </gazebo>
  <!-- fake gripper_link joint gives us a free servo!
         this makes us 5DOF and saves you $44.90
         that's a lot of coin! -->
  <link name="gripper_link"/>
  <joint name="gripper_link_joint" type="revolute">
    <origin rpy="0 -1.57 0" xyz="0 0 0.112"/>
    <parent link="arm4_link"/>
    <child link="gripper_link"/>
    <limit effort="30" lower="-3.14" upper="3.14" velocity="1"/>
    <axis xyz="1 0 0"/>
  </joint>
  <joint name="arm4_F3_joint" type="fixed">
    <origin rpy="0 3.14159265359 -1.570796326795" xyz="0 0.016 0.0265"/>
    <parent link="arm4_link"/>
    <child link="arm4_F3_link"/>
  </joint>
  <link name="arm4_F3_link">
    <visual>
      <origin rpy="0 0 0" xyz="0 0 0"/>
      <geometry>
        <mesh filename="package://jupiterobot2_arm_description/meshes/F3.stl" scale="0.001 0.001 0.001"/>
      </geometry>
      <material name="White"/>
    </visual>
    <collision>
      <origin rpy="0 0 0" xyz="0.0 0.0 -0.0045"/>
      <geometry>
        <box size="0.025 0.038 0.009"/>
      </geometry>
    </collision>
    <inertial>
      <origin xyz="0 0 -0.004"/>
      <!--0.025*0.038*0.008-->
      <mass value="0.005"/>
      <inertia ixx="6.2833e-07" ixy="0.0" ixz="0.0" iyy="2.870833e-07" iyz="0.0" izz="8.620833e-07"/>
    </inertial>
  </link>
  <gazebo reference="arm4_F3_link">
    <material>Gazebo/White</material>
    <selfCollide>true</selfCollide>
    <gravity>true</gravity>
  </gazebo>
  <joint name="gripper_servo_joint" type="fixed">
    <origin rpy="3.14159265359 1.570796326795 0" xyz="-0.02275 0 -0.019"/>
    <parent link="arm4_F3_link"/>
    <child link="gripper_servo_link"/>
  </joint>
  <link name="gripper_servo_link">
    <visual>
      <origin rpy="0 0 0" xyz="0 0 0"/>
      <geometry>
        <mesh filename="package://jupiterobot2_arm_description/meshes/ax12_box.stl" scale="0.001 0.001 0.001"/>
      </geometry>
      <material name="Black"/>
    </visual>
    <collision>
      <origin rpy="0 0 0" xyz="0.0 0.0 -0.01241"/>
      <geometry>
        <box size="0.025 0.038 0.04762"/>
      </geometry>
    </collision>
    <inertial>
      <origin xyz="0 0 0"/>
      <mass value="0.055"/>
      <inertia ixx="0.000017012" ixy="0.0" ixz="0.0" iyy="0.000013258" iyz="0.0" izz="0.000009483"/>
    </inertial>
  </link>
  <gazebo reference="gripper_servo_link">
    <material>Gazebo/Black</material>
    <selfCollide>true</selfCollide>
    <gravity>true</gravity>
  </gazebo>
  <!-- finger 1 -->
  <joint name="gripper_joint" type="revolute">
    <origin rpy="0 0 0" xyz="0 0 0"/>
    <axis xyz="0 1 0"/>
    <limit effort="30" lower="-0.40" upper="0.46" velocity="0.785"/>
    <parent link="gripper_servo_link"/>
    <child link="gripper_active_link"/>
  </joint>
  <link name="gripper_active_link">
    <inertial>
      <mass value="0.010"/>
      <origin xyz="0 0 0"/>
      <inertia ixx="0.000001" ixy="0.0" ixz="0.0" iyy="0.000001" iyz="0.0" izz="0.000001"/>
    </inertial>
    <visual>
      <origin rpy="0 0 0" xyz="0 0 0"/>
      <geometry>
        <mesh filename="package://jupiterobot2_arm_description/meshes/F2.stl" scale="0.001 0.001 0.001"/>
      </geometry>
      <material name="White"/>
    </visual>
    <collision>
      <origin rpy="0 0 0" xyz="0.0 0.0 0.00775"/>
      <geometry>
        <box size="0.025 0.0485 0.0375"/>
      </geometry>
    </collision>
  </link>
  <joint name="gripper_active_finger_joint" type="fixed">
    <origin rpy="3.14159265359 0 0" xyz="-0.013 0.017 0.0295"/>
    <parent link="gripper_active_link"/>
    <child link="gripper_active_finger_link"/>
  </joint>
  <link name="gripper_active_finger_link">
    <visual>
      <origin rpy="0 0 0" xyz="0 0 0"/>
      <geometry>
        <mesh filename="package://jupiterobot2_arm_description/meshes/finger_active.stl" scale="0.001 0.001 0.001"/>
      </geometry>
      <material name="Black"/>
    </visual>
    <collision>
      <origin rpy="0 0 0" xyz="0.0535 0.017 0.0105"/>
      <geometry>
        <box size="0.107 0.034 0.021"/>
      </geometry>
    </collision>
    <inertial>
      <origin rpy="0 0 0" xyz="0.0535 0.017 0.0105"/>
      <mass value="0.009"/>
      <inertia ixx="1.19775e-06" ixy="0" ixz="0" iyy="8.9175e-06" iyz="0" izz="9.45375e-06"/>
    </inertial>
  </link>
  <gazebo reference="gripper_active_finger_link">
    <material>Gazebo/Black</material>
    <selfCollide>true</selfCollide>
    <gravity>true</gravity>
  </gazebo>
  <joint name="gripper_static_joint" type="fixed">
    <origin rpy="0 3.14159265359 0" xyz="0 0 -0.041499999999999995"/>
    <parent link="gripper_servo_link"/>
    <child link="gripper_static_link"/>
  </joint>
  <link name="gripper_static_link">
    <visual>
      <origin rpy="0 0 0" xyz="0 0 0"/>
      <geometry>
        <mesh filename="package://jupiterobot2_arm_description/meshes/F3.stl" scale="0.001 0.001 0.001"/>
      </geometry>
      <material name="White"/>
    </visual>
    <collision>
      <origin rpy="0 0 0" xyz="0.0 0.0 -0.0045"/>
      <geometry>
        <box size="0.025 0.038 0.009"/>
      </geometry>
    </collision>
    <inertial>
      <origin xyz="0 0 -0.004"/>
      <!--0.025*0.038*0.008-->
      <mass value="0.005"/>
      <inertia ixx="6.2833e-07" ixy="0.0" ixz="0.0" iyy="2.870833e-07" iyz="0.0" izz="8.620833e-07"/>
    </inertial>
  </link>
  <gazebo reference="gripper_static_link">
    <material>Gazebo/White</material>
    <selfCollide>true</selfCollide>
    <gravity>true</gravity>
  </gazebo>
  <joint name="gripper_static_finger_joint" type="fixed">
    <origin rpy="0 0 3.14159265359" xyz="0.013 0.017 0"/>
    <parent link="gripper_static_link"/>
    <child link="gripper_static_finger_link"/>
  </joint>
  <link name="gripper_static_finger_link">
    <visual>
      <origin rpy="0 0 0" xyz="0 0 0"/>
      <geometry>
        <mesh filename="package://jupiterobot2_arm_description/meshes/finger_static.stl" scale="0.001 0.001 0.001"/>
      </geometry>
      <material name="Black"/>
    </visual>
    <collision>
      <origin rpy="0 0 0" xyz="0.045 0.017 0.0065"/>
      <geometry>
        <box size="0.09 0.034 0.013"/>
      </geometry>
    </collision>
    <inertial>
      <origin rpy="0 0 0" xyz="0.045 0.017 0.0065"/>
      <mass value="0.0075"/>
      <inertia ixx="8.28125e-07" ixy="0" ixz="0" iyy="5.168125e-06" iyz="0" izz="5.785e-06"/>
    </inertial>
  </link>
  <gazebo reference="gripper_static_finger_link">
    <material>Gazebo/Black</material>
    <selfCollide>true</selfCollide>
    <gravity>true</gravity>
  </gazebo>
  <transmission name="tran1">
    <type>transmission_interface/SimpleTransmission</type>
    <joint name="arm1_joint">
      <hardwareInterface>hardware_interface/PositionJointInterface</hardwareInterface>
    </joint>
    <actuator name="motor1">
      <hardwareInterface>hardware_interface/PositionJointInterface</hardwareInterface>
      <mechanicalReduction>1</mechanicalReduction>
    </actuator>
  </transmission>
  <transmission name="tran2">
    <type>transmission_interface/SimpleTransmission</type>
    <joint name="arm2_joint">
      <hardwareInterface>hardware_interface/PositionJointInterface</hardwareInterface>
    </joint>
    <actuator name="motor2">
      <hardwareInterface>hardware_interface/PositionJointInterface</hardwareInterface>
      <mechanicalReduction>1</mechanicalReduction>
    </actuator>
  </transmission>
  <transmission name="tran3">
    <type>transmission_interface/SimpleTransmission</type>
    <joint name="arm3_joint">
      <hardwareInterface>hardware_interface/PositionJointInterface</hardwareInterface>
    </joint>
    <actuator name="motor3">
      <hardwareInterface>hardware_interface/PositionJointInterface</hardwareInterface>
      <mechanicalReduction>1</mechanicalReduction>
    </actuator>
  </transmission>
  <transmission name="tran4">
    <type>transmission_interface/SimpleTransmission</type>
    <joint name="arm4_joint">
      <hardwareInterface>hardware_interface/PositionJointInterface</hardwareInterface>
    </joint>
    <actuator name="motor4">
      <hardwareInterface>hardware_interface/PositionJointInterface</hardwareInterface>
      <mechanicalReduction>1</mechanicalReduction>
    </actuator>
  </transmission>
  <transmission name="tran5">
    <type>transmission_interface/SimpleTransmission</type>
    <joint name="gripper_joint">
      <hardwareInterface>hardware_interface/PositionJointInterface</hardwareInterface>
    </joint>
    <actuator name="motor5">
      <hardwareInterface>hardware_interface/PositionJointInterface</hardwareInterface>
      <mechanicalReduction>1</mechanicalReduction>
    </actuator>
  </transmission>
  <!-- ros_control plugin -->
  <gazebo>
    <plugin filename="libgazebo_ros_control.so" name="gazebo_ros_control">
      <controlPeriod>0.001</controlPeriod>
      <robotNamespace>/</robotNamespace>
      <robotSimType>gazebo_ros_control/DefaultRobotHWSim</robotSimType>
      <legacyModeNS>true</legacyModeNS>
    </plugin>
  </gazebo>
</robot>

